<?xml version="1.0"?>
<!-- =================================================================================== -->
<!-- |    This document was autogenerated by xacro from rov_xacro.sdf                  | -->
<!-- |    EDITING THIS FILE BY HAND IS NOT RECOMMENDED                                 | -->
<!-- =================================================================================== -->
<sdf version="1.6">
    <model name="rov">
        <link name="base_link">
            <inertial>
                <pose> 0 0 0 0 0 0 </pose>
                <mass>10</mass>
                <inertia>
                    <ixx>0.09873097998042396</ixx>
                    <ixy>0</ixy>
                    <ixz>0</ixz>
                    <iyy>0.17756847998042397</iyy>
                    <iyz>0</iyz>
                    <izz>0.2692441666666667</izz>
                </inertia>
            </inertial>
            <visual name="base_link_visual">
                <geometry>
                    <mesh>
                        <uri>model://meshes/rov_model.dae</uri>
                        <scale />
                    </mesh>
                    <!-- <box>
                        <size>0.2 0.2 0.2</size>
                    </box> -->
                </geometry>
            </visual>
            <!-- displaced mass used by BuoyancyPlugin-->
            <collision name="base_link_collision">
                <pose>0 0 0.06 0 0 0</pose>
                <geometry>
                    <box>
                        <size>0.457 0.338 0.065</size>
                    </box>
                </geometry>
            </collision>
        </link>
        <plugin filename="gz-sim-hydrodynamics-system" name="gz::sim::systems::Hydrodynamics">
            <link_name>base_link</link_name>
            <water_density>1000</water_density>
            <!-- TODO: Update these to match our actual ROV. Currently using constants from
                Orca4/BlueRov2 -->
            <!-- Added Mass. Used for Fossen's equations -->
            <xDotU>0</xDotU>
            <yDotU>0</yDotU>
            <zDotU>0</zDotU>
            <kDotU>0</kDotU>
            <mDotU>0</mDotU>
            <nDotU>0</nDotU>
            <!-- First Order Stability Derivative. Used for Fossen's-->
            <xU>0</xU>
            <yV>0</yV>
            <zW>0</zW>
            <kP>0</kP>
            <mQ>0</mQ>
            <nR>0</nR>
            <!-- Second Order Stability Derivative. Fossen's Equations -->
            <xUabsU>-33.800000000000004</xUabsU>
            <yVabsV>-54.26875</yVabsV>
            <zWabsW>-73.37135</zWabsW>
            <kPabsP>-4.0</kPabsP>
            <mQabsQ>-4.0</mQabsQ>
            <nRabsR>-4.0</nRabsR>
        </plugin>
        <link name="thruster1">
            <pose>0.2032 0.25387 0 0 3.141592653589793 0</pose>
            <visual name="thruster_prop_visual">
                <pose>0 0 0 -1.570796 0 0</pose>
                <geometry>
                    <mesh>
                        <uri>model://meshes/t200-cw-prop.dae</uri>
                    </mesh>
                </geometry>
            </visual>
            <inertial>
                <mass>0.002</mass>
                <inertia>
                    <ixx>0.001</ixx>
                    <ixy>0</ixy>
                    <ixz>0</ixz>
                    <iyy>0.001</iyy>
                    <iyz>0</iyz>
                    <izz>0.001</izz>
                </inertia>
            </inertial>
        </link>
        <joint name="thruster1_joint" type="revolute">
            <parent>base_link</parent>
            <child>thruster1</child>
            <axis>
                <xyz>0 0 -1</xyz>
            </axis>
        </joint>
        <plugin filename="gz-sim-thruster-system" name="gz::sim::systems::Thruster">
            <namespace>rov</namespace>
            <joint_name>thruster1_joint</joint_name>
            <thrust_coefficient>0.02</thrust_coefficient>
            <fluid_density>1000</fluid_density>
            <propeller_diameter>0.1</propeller_diameter>
            <velocity_control>true</velocity_control>
            <use_angvel_cmd>False</use_angvel_cmd>
        </plugin>
        <link name="thruster2">
            <pose>-0.2032 0.25387 0 0 3.141592653589793 0</pose>
            <visual name="thruster_prop_visual">
                <pose>0 0 0 -1.570796 0 0</pose>
                <geometry>
                    <mesh>
                        <uri>model://meshes/t200-ccw-prop.dae</uri>
                    </mesh>
                </geometry>
            </visual>
            <inertial>
                <mass>0.002</mass>
                <inertia>
                    <ixx>0.001</ixx>
                    <ixy>0</ixy>
                    <ixz>0</ixz>
                    <iyy>0.001</iyy>
                    <iyz>0</iyz>
                    <izz>0.001</izz>
                </inertia>
            </inertial>
        </link>
        <joint name="thruster2_joint" type="revolute">
            <parent>base_link</parent>
            <child>thruster2</child>
            <axis>
                <xyz>0 0 -1</xyz>
            </axis>
        </joint>
        <plugin filename="gz-sim-thruster-system" name="gz::sim::systems::Thruster">
            <namespace>rov</namespace>
            <joint_name>thruster2_joint</joint_name>
            <thrust_coefficient>0.02</thrust_coefficient>
            <fluid_density>1000</fluid_density>
            <propeller_diameter>0.1</propeller_diameter>
            <velocity_control>true</velocity_control>
            <use_angvel_cmd>False</use_angvel_cmd>
        </plugin>
        <link name="thruster3">
            <pose>0.2032 -0.25387 0 0 3.141592653589793 0</pose>
            <visual name="thruster_prop_visual">
                <pose>0 0 0 -1.570796 0 0</pose>
                <geometry>
                    <mesh>
                        <uri>model://meshes/t200-ccw-prop.dae</uri>
                    </mesh>
                </geometry>
            </visual>
            <inertial>
                <mass>0.002</mass>
                <inertia>
                    <ixx>0.001</ixx>
                    <ixy>0</ixy>
                    <ixz>0</ixz>
                    <iyy>0.001</iyy>
                    <iyz>0</iyz>
                    <izz>0.001</izz>
                </inertia>
            </inertial>
        </link>
        <joint name="thruster3_joint" type="revolute">
            <parent>base_link</parent>
            <child>thruster3</child>
            <axis>
                <xyz>0 0 -1</xyz>
            </axis>
        </joint>
        <plugin filename="gz-sim-thruster-system" name="gz::sim::systems::Thruster">
            <namespace>rov</namespace>
            <joint_name>thruster3_joint</joint_name>
            <thrust_coefficient>0.02</thrust_coefficient>
            <fluid_density>1000</fluid_density>
            <propeller_diameter>0.1</propeller_diameter>
            <velocity_control>true</velocity_control>
            <use_angvel_cmd>False</use_angvel_cmd>
        </plugin>
        <link name="thruster4">
            <pose>-0.2032 -0.25387 0 0 3.141592653589793 0</pose>
            <visual name="thruster_prop_visual">
                <pose>0 0 0 -1.570796 0 0</pose>
                <geometry>
                    <mesh>
                        <uri>model://meshes/t200-cw-prop.dae</uri>
                    </mesh>
                </geometry>
            </visual>
            <inertial>
                <mass>0.002</mass>
                <inertia>
                    <ixx>0.001</ixx>
                    <ixy>0</ixy>
                    <ixz>0</ixz>
                    <iyy>0.001</iyy>
                    <iyz>0</iyz>
                    <izz>0.001</izz>
                </inertia>
            </inertial>
        </link>
        <joint name="thruster4_joint" type="revolute">
            <parent>base_link</parent>
            <child>thruster4</child>
            <axis>
                <xyz>0 0 -1</xyz>
            </axis>
        </joint>
        <plugin filename="gz-sim-thruster-system" name="gz::sim::systems::Thruster">
            <namespace>rov</namespace>
            <joint_name>thruster4_joint</joint_name>
            <thrust_coefficient>0.02</thrust_coefficient>
            <fluid_density>1000</fluid_density>
            <propeller_diameter>0.1</propeller_diameter>
            <velocity_control>true</velocity_control>
            <use_angvel_cmd>False</use_angvel_cmd>
        </plugin>
        <link name="thruster5">
            <pose>0.152482888 0.152482888 -0.049000000 1.5707963267948966 0 0.7853981633974483</pose>
            <visual name="thruster_prop_visual">
                <pose>0 0 0 -1.570796 0 0</pose>
                <geometry>
                    <mesh>
                        <uri>model://meshes/t200-cw-prop.dae</uri>
                    </mesh>
                </geometry>
            </visual>
            <inertial>
                <mass>0.002</mass>
                <inertia>
                    <ixx>0.001</ixx>
                    <ixy>0</ixy>
                    <ixz>0</ixz>
                    <iyy>0.001</iyy>
                    <iyz>0</iyz>
                    <izz>0.001</izz>
                </inertia>
            </inertial>
        </link>
        <joint name="thruster5_joint" type="revolute">
            <parent>base_link</parent>
            <child>thruster5</child>
            <axis>
                <xyz>0 0 -1</xyz>
            </axis>
        </joint>
        <plugin filename="gz-sim-thruster-system" name="gz::sim::systems::Thruster">
            <namespace>rov</namespace>
            <joint_name>thruster5_joint</joint_name>
            <thrust_coefficient>0.02</thrust_coefficient>
            <fluid_density>1000</fluid_density>
            <propeller_diameter>0.1</propeller_diameter>
            <velocity_control>true</velocity_control>
            <use_angvel_cmd>False</use_angvel_cmd>
        </plugin>
        <link name="thruster6">
            <pose>-0.152482888 0.152482888 -0.049000000 0 0 0</pose>
            <visual name="thruster_prop_visual">
                <pose>0 0 0 -1.570796 0 0</pose>
                <geometry>
                    <mesh>
                        <uri>model://meshes/t200-cw-prop.dae</uri>
                    </mesh>
                </geometry>
            </visual>
            <inertial>
                <mass>0.002</mass>
                <inertia>
                    <ixx>0.001</ixx>
                    <ixy>0</ixy>
                    <ixz>0</ixz>
                    <iyy>0.001</iyy>
                    <iyz>0</iyz>
                    <izz>0.001</izz>
                </inertia>
            </inertial>
        </link>
        <joint name="thruster6_joint" type="revolute">
            <parent>base_link</parent>
            <child>thruster6</child>
            <axis>
                <xyz>0 0 -1</xyz>
            </axis>
        </joint>
        <plugin filename="gz-sim-thruster-system" name="gz::sim::systems::Thruster">
            <namespace>rov</namespace>
            <joint_name>thruster6_joint</joint_name>
            <thrust_coefficient>0.02</thrust_coefficient>
            <fluid_density>1000</fluid_density>
            <propeller_diameter>0.1</propeller_diameter>
            <velocity_control>true</velocity_control>
            <use_angvel_cmd>False</use_angvel_cmd>
        </plugin>
        <link name="thruster7">
            <pose>0.152482888 -0.152482888 -0.049000000 0 0 0</pose>
            <visual name="thruster_prop_visual">
                <pose>0 0 0 -1.570796 0 0</pose>
                <geometry>
                    <mesh>
                        <uri>model://meshes/t200-cw-prop.dae</uri>
                    </mesh>
                </geometry>
            </visual>
            <inertial>
                <mass>0.002</mass>
                <inertia>
                    <ixx>0.001</ixx>
                    <ixy>0</ixy>
                    <ixz>0</ixz>
                    <iyy>0.001</iyy>
                    <iyz>0</iyz>
                    <izz>0.001</izz>
                </inertia>
            </inertial>
        </link>
        <joint name="thruster7_joint" type="revolute">
            <parent>base_link</parent>
            <child>thruster7</child>
            <axis>
                <xyz>0 0 -1</xyz>
            </axis>
        </joint>
        <plugin filename="gz-sim-thruster-system" name="gz::sim::systems::Thruster">
            <namespace>rov</namespace>
            <joint_name>thruster7_joint</joint_name>
            <thrust_coefficient>0.02</thrust_coefficient>
            <fluid_density>1000</fluid_density>
            <propeller_diameter>0.1</propeller_diameter>
            <velocity_control>true</velocity_control>
            <use_angvel_cmd>False</use_angvel_cmd>
        </plugin>
        <link name="thruster8">
            <pose>-0.152482888 -0.152482888 -0.049000000 0 0 0</pose>
            <visual name="thruster_prop_visual">
                <pose>0 0 0 -1.570796 0 0</pose>
                <geometry>
                    <mesh>
                        <uri>model://meshes/t200-cw-prop.dae</uri>
                    </mesh>
                </geometry>
            </visual>
            <inertial>
                <mass>0.002</mass>
                <inertia>
                    <ixx>0.001</ixx>
                    <ixy>0</ixy>
                    <ixz>0</ixz>
                    <iyy>0.001</iyy>
                    <iyz>0</iyz>
                    <izz>0.001</izz>
                </inertia>
            </inertial>
        </link>
        <joint name="thruster8_joint" type="revolute">
            <parent>base_link</parent>
            <child>thruster8</child>
            <axis>
                <xyz>0 0 -1</xyz>
            </axis>
        </joint>
        <plugin filename="gz-sim-thruster-system" name="gz::sim::systems::Thruster">
            <namespace>rov</namespace>
            <joint_name>thruster8_joint</joint_name>
            <thrust_coefficient>0.02</thrust_coefficient>
            <fluid_density>1000</fluid_density>
            <propeller_diameter>0.1</propeller_diameter>
            <velocity_control>true</velocity_control>
            <use_angvel_cmd>False</use_angvel_cmd>
        </plugin>
        <!-- <xacro:include filename="cam2.xacro"/>
            <xacro:include filename="camera.xacro" />
            <xacro:lowlight_cam name="front_cam" parent="base_link" xyz="1 1 1" rpy="0 0 0" /> -->
        <model name="front_cam">
            <pose>0 0.214757 0.09108 0 0.0 1.5707963267948966</pose>
            <link name="link">
                <pose>0 0 0 0 0 0</pose>
                <!-- <inertial>
                            <mass>0.1</mass>
                            <inertia>
                                <ixx>0.000166667</ixx>
                                <iyy>0.000166667</iyy>
                                <izz>0.000166667</izz>
                            </inertia>
                        </inertial> -->
                <collision name="collision">
                    <geometry>
                        <box>
                            <size>0.1 0.1 0.1</size>
                        </box>
                    </geometry>
                </collision>
                <visual name="visual">
                    <geometry>
                        <box>
                            <size>0.1 0.1 0.1</size>
                        </box>
                    </geometry>
                </visual>
                <sensor name="camera" type="camera">
                    <camera>
                        <horizontal_fov>1.047</horizontal_fov>
                        <image>
                            <width>320</width>
                            <height>240</height>
                        </image>
                        <clip>
                            <near>0.1</near>
                            <far>100</far>
                        </clip>
                    </camera>
                    <always_on>true</always_on>
                    <!-- <update_rate>0</update_rate> -->
                    <visualize>false</visualize>
                    <topic>our_camera</topic>
                </sensor>
            </link>
        </model>
        <joint name="base_to_cam_joint" type="fixed">
            <parent>base_link</parent>
            <child>front_cam::link</child>
        </joint>
    </model>
</sdf>