<robot xmlns:xacro="http://www.ros.org/wiki/xacro">
    <xacro:macro name="t200_thruster" params="name pose prop_type">
        <link name="${name}">
            <pose>${pose}</pose>
            <visual name="thruster_prop_visual">
                <pose>0 0 0 -1.570796 0 0</pose>
                <geometry>
                    <mesh>
                        <uri>model://meshes/t200-${prop_type}-prop.dae</uri>
                    </mesh>
                </geometry>
            </visual>
            <inertial>
                <mass>0.002</mass>
                <inertia>
                    <ixx>0.001</ixx>
                    <ixy>0</ixy>
                    <ixz>0</ixz>
                    <iyy>0.001</iyy>
                    <iyz>0</iyz>
                    <izz>0.001</izz>
                </inertia>
            </inertial>
        </link>

        <joint name="${name}_joint" type="revolute">
            <parent>base_link</parent>
            <child>${name}</child>
            <axis>
                <xyz>0 0 -1</xyz>
            </axis>
        </joint>

        <plugin
            filename="gz-sim-thruster-system"
            name="gz::sim::systems::Thruster">
            <namespace>rov</namespace>
            <joint_name>${name}_joint</joint_name>
            <thrust_coefficient>0.02</thrust_coefficient>
            <fluid_density>1000</fluid_density>
            <propeller_diameter>0.1</propeller_diameter>
            <velocity_control>true</velocity_control>
            <use_angvel_cmd>False</use_angvel_cmd>
        </plugin>
    </xacro:macro>
</robot>